Traceback (most recent call last):
  File "/usr/lib/python3.6/site-packages/urllib3/connection.py", line 162, in _new_conn
    (self._dns_host, self.port), self.timeout, **extra_kw)
  File "/usr/lib/python3.6/site-packages/urllib3/util/connection.py", line 80, in create_connection
    raise err
  File "/usr/lib/python3.6/site-packages/urllib3/util/connection.py", line 70, in create_connection
    sock.connect(sa)
ConnectionRefusedError: [Errno 111] Connection refused

During handling of the above exception, another exception occurred:

Traceback (most recent call last):
  File "/usr/lib/python3.6/site-packages/urllib3/connectionpool.py", line 600, in urlopen
    chunked=chunked)
  File "/usr/lib/python3.6/site-packages/urllib3/connectionpool.py", line 354, in _make_request
    conn.request(method, url, **httplib_request_kw)
  File "/usr/lib64/python3.6/http/client.py", line 1269, in request
    self._send_request(method, url, body, headers, encode_chunked)
  File "/usr/lib64/python3.6/http/client.py", line 1315, in _send_request
    self.endheaders(body, encode_chunked=encode_chunked)
  File "/usr/lib64/python3.6/http/client.py", line 1264, in endheaders
    self._send_output(message_body, encode_chunked=encode_chunked)
  File "/usr/lib64/python3.6/http/client.py", line 1040, in _send_output
    self.send(msg)
  File "/usr/lib64/python3.6/http/client.py", line 978, in send
    self.connect()
  File "/usr/lib/python3.6/site-packages/urllib3/connection.py", line 184, in connect
    conn = self._new_conn()
  File "/usr/lib/python3.6/site-packages/urllib3/connection.py", line 171, in _new_conn
    self, "Failed to establish a new connection: %s" % e)
urllib3.exceptions.NewConnectionError: <urllib3.connection.HTTPConnection object at 0x7f1ce914bf28>: Failed to establish a new connection: [Errno 111] Connection refused

During handling of the above exception, another exception occurred:

Traceback (most recent call last):
  File "/usr/lib/python3.6/site-packages/requests/adapters.py", line 449, in send
    timeout=timeout
  File "/usr/lib/python3.6/site-packages/urllib3/connectionpool.py", line 638, in urlopen
    _stacktrace=sys.exc_info()[2])
  File "/usr/lib/python3.6/site-packages/urllib3/util/retry.py", line 399, in increment
    raise MaxRetryError(_pool, url, error or ResponseError(cause))
urllib3.exceptions.MaxRetryError: HTTPConnectionPool(host='localhost', port=3001): Max retries exceeded with url: /messages/root (Caused by NewConnectionError('<urllib3.connection.HTTPConnection object at 0x7f1ce914bf28>: Failed to establish a new connection: [Errno 111] Connection refused',))

During handling of the above exception, another exception occurred:

Traceback (most recent call last):
  File "main.py", line 48, in <module>
    bot.polling()
  File "/usr/local/lib/python3.6/site-packages/telebot/__init__.py", line 658, in polling
    self.__threaded_polling(non_stop, interval, timeout, long_polling_timeout, allowed_updates)
  File "/usr/local/lib/python3.6/site-packages/telebot/__init__.py", line 720, in __threaded_polling
    raise e
  File "/usr/local/lib/python3.6/site-packages/telebot/__init__.py", line 680, in __threaded_polling
    self.worker_pool.raise_exceptions()
  File "/usr/local/lib/python3.6/site-packages/telebot/util.py", line 135, in raise_exceptions
    raise self.exception_info
  File "/usr/local/lib/python3.6/site-packages/telebot/util.py", line 87, in run
    task(*args, **kwargs)
  File "main.py", line 45, in start
    question = getFirst()
  File "main.py", line 12, in getFirst
    response = requests.get("{base_url}/messages/root".format(base_url=BASE_URL))
  File "/usr/lib/python3.6/site-packages/requests/api.py", line 75, in get
    return request('get', url, params=params, **kwargs)
  File "/usr/lib/python3.6/site-packages/requests/api.py", line 60, in request
    return session.request(method=method, url=url, **kwargs)
  File "/usr/lib/python3.6/site-packages/requests/sessions.py", line 533, in request
    resp = self.send(prep, **send_kwargs)
  File "/usr/lib/python3.6/site-packages/requests/sessions.py", line 646, in send
    r = adapter.send(request, **kwargs)
  File "/usr/lib/python3.6/site-packages/requests/adapters.py", line 516, in send
    raise ConnectionError(e, request=request)
requests.exceptions.ConnectionError: HTTPConnectionPool(host='localhost', port=3001): Max retries exceeded with url: /messages/root (Caused by NewConnectionError('<urllib3.connection.HTTPConnection object at 0x7f1ce914bf28>: Failed to establish a new connection: [Errno 111] Connection refused',))
<Response [200]>
Traceback (most recent call last):
  File "/usr/lib/python3.6/site-packages/urllib3/connection.py", line 162, in _new_conn
    (self._dns_host, self.port), self.timeout, **extra_kw)
  File "/usr/lib/python3.6/site-packages/urllib3/util/connection.py", line 80, in create_connection
    raise err
  File "/usr/lib/python3.6/site-packages/urllib3/util/connection.py", line 70, in create_connection
    sock.connect(sa)
ConnectionRefusedError: [Errno 111] Connection refused

During handling of the above exception, another exception occurred:

Traceback (most recent call last):
  File "/usr/lib/python3.6/site-packages/urllib3/connectionpool.py", line 600, in urlopen
    chunked=chunked)
  File "/usr/lib/python3.6/site-packages/urllib3/connectionpool.py", line 354, in _make_request
    conn.request(method, url, **httplib_request_kw)
  File "/usr/lib64/python3.6/http/client.py", line 1269, in request
    self._send_request(method, url, body, headers, encode_chunked)
  File "/usr/lib64/python3.6/http/client.py", line 1315, in _send_request
    self.endheaders(body, encode_chunked=encode_chunked)
  File "/usr/lib64/python3.6/http/client.py", line 1264, in endheaders
    self._send_output(message_body, encode_chunked=encode_chunked)
  File "/usr/lib64/python3.6/http/client.py", line 1040, in _send_output
    self.send(msg)
  File "/usr/lib64/python3.6/http/client.py", line 978, in send
    self.connect()
  File "/usr/lib/python3.6/site-packages/urllib3/connection.py", line 184, in connect
    conn = self._new_conn()
  File "/usr/lib/python3.6/site-packages/urllib3/connection.py", line 171, in _new_conn
    self, "Failed to establish a new connection: %s" % e)
urllib3.exceptions.NewConnectionError: <urllib3.connection.HTTPConnection object at 0x7fd5aa080ef0>: Failed to establish a new connection: [Errno 111] Connection refused

During handling of the above exception, another exception occurred:

Traceback (most recent call last):
  File "/usr/lib/python3.6/site-packages/requests/adapters.py", line 449, in send
    timeout=timeout
  File "/usr/lib/python3.6/site-packages/urllib3/connectionpool.py", line 638, in urlopen
    _stacktrace=sys.exc_info()[2])
  File "/usr/lib/python3.6/site-packages/urllib3/util/retry.py", line 399, in increment
    raise MaxRetryError(_pool, url, error or ResponseError(cause))
urllib3.exceptions.MaxRetryError: HTTPConnectionPool(host='localhost', port=3001): Max retries exceeded with url: /messages/root (Caused by NewConnectionError('<urllib3.connection.HTTPConnection object at 0x7fd5aa080ef0>: Failed to establish a new connection: [Errno 111] Connection refused',))

During handling of the above exception, another exception occurred:

Traceback (most recent call last):
  File "main.py", line 48, in <module>
    bot.polling()
  File "/usr/local/lib/python3.6/site-packages/telebot/__init__.py", line 658, in polling
    self.__threaded_polling(non_stop, interval, timeout, long_polling_timeout, allowed_updates)
  File "/usr/local/lib/python3.6/site-packages/telebot/__init__.py", line 720, in __threaded_polling
    raise e
  File "/usr/local/lib/python3.6/site-packages/telebot/__init__.py", line 680, in __threaded_polling
    self.worker_pool.raise_exceptions()
  File "/usr/local/lib/python3.6/site-packages/telebot/util.py", line 135, in raise_exceptions
    raise self.exception_info
  File "/usr/local/lib/python3.6/site-packages/telebot/util.py", line 87, in run
    task(*args, **kwargs)
  File "main.py", line 45, in start
    question = getFirst()
  File "main.py", line 12, in getFirst
    response = requests.get("{base_url}/messages/root".format(base_url=BASE_URL))
  File "/usr/lib/python3.6/site-packages/requests/api.py", line 75, in get
    return request('get', url, params=params, **kwargs)
  File "/usr/lib/python3.6/site-packages/requests/api.py", line 60, in request
    return session.request(method=method, url=url, **kwargs)
  File "/usr/lib/python3.6/site-packages/requests/sessions.py", line 533, in request
    resp = self.send(prep, **send_kwargs)
  File "/usr/lib/python3.6/site-packages/requests/sessions.py", line 646, in send
    r = adapter.send(request, **kwargs)
  File "/usr/lib/python3.6/site-packages/requests/adapters.py", line 516, in send
    raise ConnectionError(e, request=request)
requests.exceptions.ConnectionError: HTTPConnectionPool(host='localhost', port=3001): Max retries exceeded with url: /messages/root (Caused by NewConnectionError('<urllib3.connection.HTTPConnection object at 0x7fd5aa080ef0>: Failed to establish a new connection: [Errno 111] Connection refused',))
<Response [200]>
<Response [200]>
<Response [200]>
<Response [200]>
<Response [200]>
<Response [200]>
<Response [200]>
<Response [200]>
<Response [200]>
<Response [200]>
<Response [200]>
<Response [200]>
<Response [200]>
Traceback (most recent call last):
  File "/usr/lib/python3.6/site-packages/urllib3/connectionpool.py", line 384, in _make_request
    six.raise_from(e, None)
  File "<string>", line 3, in raise_from
  File "/usr/lib/python3.6/site-packages/urllib3/connectionpool.py", line 380, in _make_request
    httplib_response = conn.getresponse()
  File "/usr/lib64/python3.6/http/client.py", line 1361, in getresponse
    response.begin()
  File "/usr/lib64/python3.6/http/client.py", line 311, in begin
    version, status, reason = self._read_status()
  File "/usr/lib64/python3.6/http/client.py", line 272, in _read_status
    line = str(self.fp.readline(_MAXLINE + 1), "iso-8859-1")
  File "/usr/lib64/python3.6/socket.py", line 586, in readinto
    return self._sock.recv_into(b)
  File "/usr/lib64/python3.6/ssl.py", line 971, in recv_into
    return self.read(nbytes, buffer)
  File "/usr/lib64/python3.6/ssl.py", line 833, in read
    return self._sslobj.read(len, buffer)
  File "/usr/lib64/python3.6/ssl.py", line 590, in read
    v = self._sslobj.read(len, buffer)
socket.timeout: The read operation timed out

During handling of the above exception, another exception occurred:

Traceback (most recent call last):
  File "/usr/lib/python3.6/site-packages/requests/adapters.py", line 449, in send
    timeout=timeout
  File "/usr/lib/python3.6/site-packages/urllib3/connectionpool.py", line 638, in urlopen
    _stacktrace=sys.exc_info()[2])
  File "/usr/lib/python3.6/site-packages/urllib3/util/retry.py", line 368, in increment
    raise six.reraise(type(error), error, _stacktrace)
  File "/usr/lib/python3.6/site-packages/urllib3/packages/six.py", line 693, in reraise
    raise value
  File "/usr/lib/python3.6/site-packages/urllib3/connectionpool.py", line 600, in urlopen
    chunked=chunked)
  File "/usr/lib/python3.6/site-packages/urllib3/connectionpool.py", line 386, in _make_request
    self._raise_timeout(err=e, url=url, timeout_value=read_timeout)
  File "/usr/lib/python3.6/site-packages/urllib3/connectionpool.py", line 306, in _raise_timeout
    raise ReadTimeoutError(self, url, "Read timed out. (read timeout=%s)" % timeout_value)
urllib3.exceptions.ReadTimeoutError: HTTPSConnectionPool(host='api.telegram.org', port=443): Read timed out. (read timeout=25)

During handling of the above exception, another exception occurred:

Traceback (most recent call last):
  File "main.py", line 48, in <module>
    bot.polling()
  File "/usr/local/lib/python3.6/site-packages/telebot/__init__.py", line 658, in polling
    self.__threaded_polling(non_stop, interval, timeout, long_polling_timeout, allowed_updates)
  File "/usr/local/lib/python3.6/site-packages/telebot/__init__.py", line 720, in __threaded_polling
    raise e
  File "/usr/local/lib/python3.6/site-packages/telebot/__init__.py", line 679, in __threaded_polling
    polling_thread.raise_exceptions()
  File "/usr/local/lib/python3.6/site-packages/telebot/util.py", line 105, in raise_exceptions
    raise self.exception_info
  File "/usr/local/lib/python3.6/site-packages/telebot/util.py", line 87, in run
    task(*args, **kwargs)
  File "/usr/local/lib/python3.6/site-packages/telebot/__init__.py", line 409, in __retrieve_updates
    timeout=timeout, long_polling_timeout=long_polling_timeout)
  File "/usr/local/lib/python3.6/site-packages/telebot/__init__.py", line 387, in get_updates
    json_updates = apihelper.get_updates(self.token, offset, limit, timeout, allowed_updates, long_polling_timeout)
  File "/usr/local/lib/python3.6/site-packages/telebot/apihelper.py", line 328, in get_updates
    return _make_request(token, method_url, params=payload)
  File "/usr/local/lib/python3.6/site-packages/telebot/apihelper.py", line 154, in _make_request
    timeout=(connect_timeout, read_timeout), proxies=proxy)
  File "/usr/lib/python3.6/site-packages/requests/sessions.py", line 533, in request
    resp = self.send(prep, **send_kwargs)
  File "/usr/lib/python3.6/site-packages/requests/sessions.py", line 646, in send
    r = adapter.send(request, **kwargs)
  File "/usr/lib/python3.6/site-packages/requests/adapters.py", line 529, in send
    raise ReadTimeout(e, request=request)
requests.exceptions.ReadTimeout: HTTPSConnectionPool(host='api.telegram.org', port=443): Read timed out. (read timeout=25)
Traceback (most recent call last):
  File "/usr/lib/python3.6/site-packages/urllib3/connection.py", line 162, in _new_conn
    (self._dns_host, self.port), self.timeout, **extra_kw)
  File "/usr/lib/python3.6/site-packages/urllib3/util/connection.py", line 80, in create_connection
    raise err
  File "/usr/lib/python3.6/site-packages/urllib3/util/connection.py", line 70, in create_connection
    sock.connect(sa)
ConnectionRefusedError: [Errno 111] Connection refused

During handling of the above exception, another exception occurred:

Traceback (most recent call last):
  File "/usr/lib/python3.6/site-packages/urllib3/connectionpool.py", line 600, in urlopen
    chunked=chunked)
  File "/usr/lib/python3.6/site-packages/urllib3/connectionpool.py", line 354, in _make_request
    conn.request(method, url, **httplib_request_kw)
  File "/usr/lib64/python3.6/http/client.py", line 1269, in request
    self._send_request(method, url, body, headers, encode_chunked)
  File "/usr/lib64/python3.6/http/client.py", line 1315, in _send_request
    self.endheaders(body, encode_chunked=encode_chunked)
  File "/usr/lib64/python3.6/http/client.py", line 1264, in endheaders
    self._send_output(message_body, encode_chunked=encode_chunked)
  File "/usr/lib64/python3.6/http/client.py", line 1040, in _send_output
    self.send(msg)
  File "/usr/lib64/python3.6/http/client.py", line 978, in send
    self.connect()
  File "/usr/lib/python3.6/site-packages/urllib3/connection.py", line 184, in connect
    conn = self._new_conn()
  File "/usr/lib/python3.6/site-packages/urllib3/connection.py", line 171, in _new_conn
    self, "Failed to establish a new connection: %s" % e)
urllib3.exceptions.NewConnectionError: <urllib3.connection.HTTPConnection object at 0x7f2a356a50f0>: Failed to establish a new connection: [Errno 111] Connection refused

During handling of the above exception, another exception occurred:

Traceback (most recent call last):
  File "/usr/lib/python3.6/site-packages/requests/adapters.py", line 449, in send
    timeout=timeout
  File "/usr/lib/python3.6/site-packages/urllib3/connectionpool.py", line 638, in urlopen
    _stacktrace=sys.exc_info()[2])
  File "/usr/lib/python3.6/site-packages/urllib3/util/retry.py", line 399, in increment
    raise MaxRetryError(_pool, url, error or ResponseError(cause))
urllib3.exceptions.MaxRetryError: HTTPConnectionPool(host='localhost', port=3001): Max retries exceeded with url: /messages/root (Caused by NewConnectionError('<urllib3.connection.HTTPConnection object at 0x7f2a356a50f0>: Failed to establish a new connection: [Errno 111] Connection refused',))

During handling of the above exception, another exception occurred:

Traceback (most recent call last):
  File "main.py", line 48, in <module>
    bot.polling()
  File "/usr/local/lib/python3.6/site-packages/telebot/__init__.py", line 658, in polling
    self.__threaded_polling(non_stop, interval, timeout, long_polling_timeout, allowed_updates)
  File "/usr/local/lib/python3.6/site-packages/telebot/__init__.py", line 720, in __threaded_polling
    raise e
  File "/usr/local/lib/python3.6/site-packages/telebot/__init__.py", line 680, in __threaded_polling
    self.worker_pool.raise_exceptions()
  File "/usr/local/lib/python3.6/site-packages/telebot/util.py", line 135, in raise_exceptions
    raise self.exception_info
  File "/usr/local/lib/python3.6/site-packages/telebot/util.py", line 87, in run
    task(*args, **kwargs)
  File "main.py", line 45, in start
    question = getFirst()
  File "main.py", line 12, in getFirst
    response = requests.get("{base_url}/messages/root".format(base_url=BASE_URL))
  File "/usr/lib/python3.6/site-packages/requests/api.py", line 75, in get
    return request('get', url, params=params, **kwargs)
  File "/usr/lib/python3.6/site-packages/requests/api.py", line 60, in request
    return session.request(method=method, url=url, **kwargs)
  File "/usr/lib/python3.6/site-packages/requests/sessions.py", line 533, in request
    resp = self.send(prep, **send_kwargs)
  File "/usr/lib/python3.6/site-packages/requests/sessions.py", line 646, in send
    r = adapter.send(request, **kwargs)
  File "/usr/lib/python3.6/site-packages/requests/adapters.py", line 516, in send
    raise ConnectionError(e, request=request)
requests.exceptions.ConnectionError: HTTPConnectionPool(host='localhost', port=3001): Max retries exceeded with url: /messages/root (Caused by NewConnectionError('<urllib3.connection.HTTPConnection object at 0x7f2a356a50f0>: Failed to establish a new connection: [Errno 111] Connection refused',))
Traceback (most recent call last):
  File "/usr/lib/python3.6/site-packages/urllib3/connection.py", line 162, in _new_conn
    (self._dns_host, self.port), self.timeout, **extra_kw)
  File "/usr/lib/python3.6/site-packages/urllib3/util/connection.py", line 80, in create_connection
    raise err
  File "/usr/lib/python3.6/site-packages/urllib3/util/connection.py", line 70, in create_connection
    sock.connect(sa)
ConnectionRefusedError: [Errno 111] Connection refused

During handling of the above exception, another exception occurred:

Traceback (most recent call last):
  File "/usr/lib/python3.6/site-packages/urllib3/connectionpool.py", line 600, in urlopen
    chunked=chunked)
  File "/usr/lib/python3.6/site-packages/urllib3/connectionpool.py", line 354, in _make_request
    conn.request(method, url, **httplib_request_kw)
  File "/usr/lib64/python3.6/http/client.py", line 1269, in request
    self._send_request(method, url, body, headers, encode_chunked)
  File "/usr/lib64/python3.6/http/client.py", line 1315, in _send_request
    self.endheaders(body, encode_chunked=encode_chunked)
  File "/usr/lib64/python3.6/http/client.py", line 1264, in endheaders
    self._send_output(message_body, encode_chunked=encode_chunked)
  File "/usr/lib64/python3.6/http/client.py", line 1040, in _send_output
    self.send(msg)
  File "/usr/lib64/python3.6/http/client.py", line 978, in send
    self.connect()
  File "/usr/lib/python3.6/site-packages/urllib3/connection.py", line 184, in connect
    conn = self._new_conn()
  File "/usr/lib/python3.6/site-packages/urllib3/connection.py", line 171, in _new_conn
    self, "Failed to establish a new connection: %s" % e)
urllib3.exceptions.NewConnectionError: <urllib3.connection.HTTPConnection object at 0x7f113d897e48>: Failed to establish a new connection: [Errno 111] Connection refused

During handling of the above exception, another exception occurred:

Traceback (most recent call last):
  File "/usr/lib/python3.6/site-packages/requests/adapters.py", line 449, in send
    timeout=timeout
  File "/usr/lib/python3.6/site-packages/urllib3/connectionpool.py", line 638, in urlopen
    _stacktrace=sys.exc_info()[2])
  File "/usr/lib/python3.6/site-packages/urllib3/util/retry.py", line 399, in increment
    raise MaxRetryError(_pool, url, error or ResponseError(cause))
urllib3.exceptions.MaxRetryError: HTTPConnectionPool(host='localhost', port=3001): Max retries exceeded with url: /messages/root (Caused by NewConnectionError('<urllib3.connection.HTTPConnection object at 0x7f113d897e48>: Failed to establish a new connection: [Errno 111] Connection refused',))

During handling of the above exception, another exception occurred:

Traceback (most recent call last):
  File "main.py", line 48, in <module>
    bot.polling()
  File "/usr/local/lib/python3.6/site-packages/telebot/__init__.py", line 658, in polling
    self.__threaded_polling(non_stop, interval, timeout, long_polling_timeout, allowed_updates)
  File "/usr/local/lib/python3.6/site-packages/telebot/__init__.py", line 720, in __threaded_polling
    raise e
  File "/usr/local/lib/python3.6/site-packages/telebot/__init__.py", line 680, in __threaded_polling
    self.worker_pool.raise_exceptions()
  File "/usr/local/lib/python3.6/site-packages/telebot/util.py", line 135, in raise_exceptions
    raise self.exception_info
  File "/usr/local/lib/python3.6/site-packages/telebot/util.py", line 87, in run
    task(*args, **kwargs)
  File "main.py", line 45, in start
    question = getFirst()
  File "main.py", line 12, in getFirst
    response = requests.get("{base_url}/messages/root".format(base_url=BASE_URL))
  File "/usr/lib/python3.6/site-packages/requests/api.py", line 75, in get
    return request('get', url, params=params, **kwargs)
  File "/usr/lib/python3.6/site-packages/requests/api.py", line 60, in request
    return session.request(method=method, url=url, **kwargs)
  File "/usr/lib/python3.6/site-packages/requests/sessions.py", line 533, in request
    resp = self.send(prep, **send_kwargs)
  File "/usr/lib/python3.6/site-packages/requests/sessions.py", line 646, in send
    r = adapter.send(request, **kwargs)
  File "/usr/lib/python3.6/site-packages/requests/adapters.py", line 516, in send
    raise ConnectionError(e, request=request)
requests.exceptions.ConnectionError: HTTPConnectionPool(host='localhost', port=3001): Max retries exceeded with url: /messages/root (Caused by NewConnectionError('<urllib3.connection.HTTPConnection object at 0x7f113d897e48>: Failed to establish a new connection: [Errno 111] Connection refused',))
<Response [200]>
<Response [200]>
<Response [200]>
<Response [200]>
Traceback (most recent call last):
  File "/usr/lib/python3.6/site-packages/urllib3/connectionpool.py", line 384, in _make_request
    six.raise_from(e, None)
  File "<string>", line 3, in raise_from
  File "/usr/lib/python3.6/site-packages/urllib3/connectionpool.py", line 380, in _make_request
    httplib_response = conn.getresponse()
  File "/usr/lib64/python3.6/http/client.py", line 1361, in getresponse
    response.begin()
  File "/usr/lib64/python3.6/http/client.py", line 311, in begin
    version, status, reason = self._read_status()
  File "/usr/lib64/python3.6/http/client.py", line 272, in _read_status
    line = str(self.fp.readline(_MAXLINE + 1), "iso-8859-1")
  File "/usr/lib64/python3.6/socket.py", line 586, in readinto
    return self._sock.recv_into(b)
  File "/usr/lib64/python3.6/ssl.py", line 971, in recv_into
    return self.read(nbytes, buffer)
  File "/usr/lib64/python3.6/ssl.py", line 833, in read
    return self._sslobj.read(len, buffer)
  File "/usr/lib64/python3.6/ssl.py", line 590, in read
    v = self._sslobj.read(len, buffer)
socket.timeout: The read operation timed out

During handling of the above exception, another exception occurred:

Traceback (most recent call last):
  File "/usr/lib/python3.6/site-packages/requests/adapters.py", line 449, in send
    timeout=timeout
  File "/usr/lib/python3.6/site-packages/urllib3/connectionpool.py", line 638, in urlopen
    _stacktrace=sys.exc_info()[2])
  File "/usr/lib/python3.6/site-packages/urllib3/util/retry.py", line 368, in increment
    raise six.reraise(type(error), error, _stacktrace)
  File "/usr/lib/python3.6/site-packages/urllib3/packages/six.py", line 693, in reraise
    raise value
  File "/usr/lib/python3.6/site-packages/urllib3/connectionpool.py", line 600, in urlopen
    chunked=chunked)
  File "/usr/lib/python3.6/site-packages/urllib3/connectionpool.py", line 386, in _make_request
    self._raise_timeout(err=e, url=url, timeout_value=read_timeout)
  File "/usr/lib/python3.6/site-packages/urllib3/connectionpool.py", line 306, in _raise_timeout
    raise ReadTimeoutError(self, url, "Read timed out. (read timeout=%s)" % timeout_value)
urllib3.exceptions.ReadTimeoutError: HTTPSConnectionPool(host='api.telegram.org', port=443): Read timed out. (read timeout=25)

During handling of the above exception, another exception occurred:

Traceback (most recent call last):
  File "main.py", line 48, in <module>
    bot.polling()
  File "/usr/local/lib/python3.6/site-packages/telebot/__init__.py", line 658, in polling
    self.__threaded_polling(non_stop, interval, timeout, long_polling_timeout, allowed_updates)
  File "/usr/local/lib/python3.6/site-packages/telebot/__init__.py", line 720, in __threaded_polling
    raise e
  File "/usr/local/lib/python3.6/site-packages/telebot/__init__.py", line 679, in __threaded_polling
    polling_thread.raise_exceptions()
  File "/usr/local/lib/python3.6/site-packages/telebot/util.py", line 105, in raise_exceptions
    raise self.exception_info
  File "/usr/local/lib/python3.6/site-packages/telebot/util.py", line 87, in run
    task(*args, **kwargs)
  File "/usr/local/lib/python3.6/site-packages/telebot/__init__.py", line 409, in __retrieve_updates
    timeout=timeout, long_polling_timeout=long_polling_timeout)
  File "/usr/local/lib/python3.6/site-packages/telebot/__init__.py", line 387, in get_updates
    json_updates = apihelper.get_updates(self.token, offset, limit, timeout, allowed_updates, long_polling_timeout)
  File "/usr/local/lib/python3.6/site-packages/telebot/apihelper.py", line 328, in get_updates
    return _make_request(token, method_url, params=payload)
  File "/usr/local/lib/python3.6/site-packages/telebot/apihelper.py", line 154, in _make_request
    timeout=(connect_timeout, read_timeout), proxies=proxy)
  File "/usr/lib/python3.6/site-packages/requests/sessions.py", line 533, in request
    resp = self.send(prep, **send_kwargs)
  File "/usr/lib/python3.6/site-packages/requests/sessions.py", line 646, in send
    r = adapter.send(request, **kwargs)
  File "/usr/lib/python3.6/site-packages/requests/adapters.py", line 529, in send
    raise ReadTimeout(e, request=request)
requests.exceptions.ReadTimeout: HTTPSConnectionPool(host='api.telegram.org', port=443): Read timed out. (read timeout=25)
Traceback (most recent call last):
  File "/usr/lib/python3.6/site-packages/urllib3/connection.py", line 162, in _new_conn
    (self._dns_host, self.port), self.timeout, **extra_kw)
  File "/usr/lib/python3.6/site-packages/urllib3/util/connection.py", line 80, in create_connection
    raise err
  File "/usr/lib/python3.6/site-packages/urllib3/util/connection.py", line 70, in create_connection
    sock.connect(sa)
ConnectionRefusedError: [Errno 111] Connection refused

During handling of the above exception, another exception occurred:

Traceback (most recent call last):
  File "/usr/lib/python3.6/site-packages/urllib3/connectionpool.py", line 600, in urlopen
    chunked=chunked)
  File "/usr/lib/python3.6/site-packages/urllib3/connectionpool.py", line 354, in _make_request
    conn.request(method, url, **httplib_request_kw)
  File "/usr/lib64/python3.6/http/client.py", line 1269, in request
    self._send_request(method, url, body, headers, encode_chunked)
  File "/usr/lib64/python3.6/http/client.py", line 1315, in _send_request
    self.endheaders(body, encode_chunked=encode_chunked)
  File "/usr/lib64/python3.6/http/client.py", line 1264, in endheaders
    self._send_output(message_body, encode_chunked=encode_chunked)
  File "/usr/lib64/python3.6/http/client.py", line 1040, in _send_output
    self.send(msg)
  File "/usr/lib64/python3.6/http/client.py", line 978, in send
    self.connect()
  File "/usr/lib/python3.6/site-packages/urllib3/connection.py", line 184, in connect
    conn = self._new_conn()
  File "/usr/lib/python3.6/site-packages/urllib3/connection.py", line 171, in _new_conn
    self, "Failed to establish a new connection: %s" % e)
urllib3.exceptions.NewConnectionError: <urllib3.connection.HTTPConnection object at 0x7f221e50c1d0>: Failed to establish a new connection: [Errno 111] Connection refused

During handling of the above exception, another exception occurred:

Traceback (most recent call last):
  File "/usr/lib/python3.6/site-packages/requests/adapters.py", line 449, in send
    timeout=timeout
  File "/usr/lib/python3.6/site-packages/urllib3/connectionpool.py", line 638, in urlopen
    _stacktrace=sys.exc_info()[2])
  File "/usr/lib/python3.6/site-packages/urllib3/util/retry.py", line 399, in increment
    raise MaxRetryError(_pool, url, error or ResponseError(cause))
urllib3.exceptions.MaxRetryError: HTTPConnectionPool(host='localhost', port=3001): Max retries exceeded with url: /messages/root (Caused by NewConnectionError('<urllib3.connection.HTTPConnection object at 0x7f221e50c1d0>: Failed to establish a new connection: [Errno 111] Connection refused',))

During handling of the above exception, another exception occurred:

Traceback (most recent call last):
  File "main.py", line 48, in <module>
    bot.polling()
  File "/usr/local/lib/python3.6/site-packages/telebot/__init__.py", line 658, in polling
    self.__threaded_polling(non_stop, interval, timeout, long_polling_timeout, allowed_updates)
  File "/usr/local/lib/python3.6/site-packages/telebot/__init__.py", line 720, in __threaded_polling
    raise e
  File "/usr/local/lib/python3.6/site-packages/telebot/__init__.py", line 680, in __threaded_polling
    self.worker_pool.raise_exceptions()
  File "/usr/local/lib/python3.6/site-packages/telebot/util.py", line 135, in raise_exceptions
    raise self.exception_info
  File "/usr/local/lib/python3.6/site-packages/telebot/util.py", line 87, in run
    task(*args, **kwargs)
  File "main.py", line 45, in start
    question = getFirst()
  File "main.py", line 12, in getFirst
    response = requests.get("{base_url}/messages/root".format(base_url=BASE_URL))
  File "/usr/lib/python3.6/site-packages/requests/api.py", line 75, in get
    return request('get', url, params=params, **kwargs)
  File "/usr/lib/python3.6/site-packages/requests/api.py", line 60, in request
    return session.request(method=method, url=url, **kwargs)
  File "/usr/lib/python3.6/site-packages/requests/sessions.py", line 533, in request
    resp = self.send(prep, **send_kwargs)
  File "/usr/lib/python3.6/site-packages/requests/sessions.py", line 646, in send
    r = adapter.send(request, **kwargs)
  File "/usr/lib/python3.6/site-packages/requests/adapters.py", line 516, in send
    raise ConnectionError(e, request=request)
requests.exceptions.ConnectionError: HTTPConnectionPool(host='localhost', port=3001): Max retries exceeded with url: /messages/root (Caused by NewConnectionError('<urllib3.connection.HTTPConnection object at 0x7f221e50c1d0>: Failed to establish a new connection: [Errno 111] Connection refused',))
<Response [200]>
<Response [200]>
<Response [200]>
<Response [200]>
<Response [200]>
<Response [200]>
Traceback (most recent call last):
  File "/usr/lib/python3.6/site-packages/urllib3/connectionpool.py", line 600, in urlopen
    chunked=chunked)
  File "/usr/lib/python3.6/site-packages/urllib3/connectionpool.py", line 384, in _make_request
    six.raise_from(e, None)
  File "<string>", line 3, in raise_from
  File "/usr/lib/python3.6/site-packages/urllib3/connectionpool.py", line 380, in _make_request
    httplib_response = conn.getresponse()
  File "/usr/lib64/python3.6/http/client.py", line 1361, in getresponse
    response.begin()
  File "/usr/lib64/python3.6/http/client.py", line 311, in begin
    version, status, reason = self._read_status()
  File "/usr/lib64/python3.6/http/client.py", line 272, in _read_status
    line = str(self.fp.readline(_MAXLINE + 1), "iso-8859-1")
  File "/usr/lib64/python3.6/socket.py", line 586, in readinto
    return self._sock.recv_into(b)
  File "/usr/lib64/python3.6/ssl.py", line 971, in recv_into
    return self.read(nbytes, buffer)
  File "/usr/lib64/python3.6/ssl.py", line 833, in read
    return self._sslobj.read(len, buffer)
  File "/usr/lib64/python3.6/ssl.py", line 590, in read
    v = self._sslobj.read(len, buffer)
ConnectionResetError: [Errno 104] Connection reset by peer

During handling of the above exception, another exception occurred:

Traceback (most recent call last):
  File "/usr/lib/python3.6/site-packages/requests/adapters.py", line 449, in send
    timeout=timeout
  File "/usr/lib/python3.6/site-packages/urllib3/connectionpool.py", line 638, in urlopen
    _stacktrace=sys.exc_info()[2])
  File "/usr/lib/python3.6/site-packages/urllib3/util/retry.py", line 368, in increment
    raise six.reraise(type(error), error, _stacktrace)
  File "/usr/lib/python3.6/site-packages/urllib3/packages/six.py", line 692, in reraise
    raise value.with_traceback(tb)
  File "/usr/lib/python3.6/site-packages/urllib3/connectionpool.py", line 600, in urlopen
    chunked=chunked)
  File "/usr/lib/python3.6/site-packages/urllib3/connectionpool.py", line 384, in _make_request
    six.raise_from(e, None)
  File "<string>", line 3, in raise_from
  File "/usr/lib/python3.6/site-packages/urllib3/connectionpool.py", line 380, in _make_request
    httplib_response = conn.getresponse()
  File "/usr/lib64/python3.6/http/client.py", line 1361, in getresponse
    response.begin()
  File "/usr/lib64/python3.6/http/client.py", line 311, in begin
    version, status, reason = self._read_status()
  File "/usr/lib64/python3.6/http/client.py", line 272, in _read_status
    line = str(self.fp.readline(_MAXLINE + 1), "iso-8859-1")
  File "/usr/lib64/python3.6/socket.py", line 586, in readinto
    return self._sock.recv_into(b)
  File "/usr/lib64/python3.6/ssl.py", line 971, in recv_into
    return self.read(nbytes, buffer)
  File "/usr/lib64/python3.6/ssl.py", line 833, in read
    return self._sslobj.read(len, buffer)
  File "/usr/lib64/python3.6/ssl.py", line 590, in read
    v = self._sslobj.read(len, buffer)
urllib3.exceptions.ProtocolError: ('Connection aborted.', ConnectionResetError(104, 'Connection reset by peer'))

During handling of the above exception, another exception occurred:

Traceback (most recent call last):
  File "main.py", line 48, in <module>
    bot.polling()
  File "/usr/local/lib/python3.6/site-packages/telebot/__init__.py", line 658, in polling
    self.__threaded_polling(non_stop, interval, timeout, long_polling_timeout, allowed_updates)
  File "/usr/local/lib/python3.6/site-packages/telebot/__init__.py", line 720, in __threaded_polling
    raise e
  File "/usr/local/lib/python3.6/site-packages/telebot/__init__.py", line 679, in __threaded_polling
    polling_thread.raise_exceptions()
  File "/usr/local/lib/python3.6/site-packages/telebot/util.py", line 105, in raise_exceptions
    raise self.exception_info
  File "/usr/local/lib/python3.6/site-packages/telebot/util.py", line 87, in run
    task(*args, **kwargs)
  File "/usr/local/lib/python3.6/site-packages/telebot/__init__.py", line 409, in __retrieve_updates
    timeout=timeout, long_polling_timeout=long_polling_timeout)
  File "/usr/local/lib/python3.6/site-packages/telebot/__init__.py", line 387, in get_updates
    json_updates = apihelper.get_updates(self.token, offset, limit, timeout, allowed_updates, long_polling_timeout)
  File "/usr/local/lib/python3.6/site-packages/telebot/apihelper.py", line 328, in get_updates
    return _make_request(token, method_url, params=payload)
  File "/usr/local/lib/python3.6/site-packages/telebot/apihelper.py", line 154, in _make_request
    timeout=(connect_timeout, read_timeout), proxies=proxy)
  File "/usr/lib/python3.6/site-packages/requests/sessions.py", line 533, in request
    resp = self.send(prep, **send_kwargs)
  File "/usr/lib/python3.6/site-packages/requests/sessions.py", line 646, in send
    r = adapter.send(request, **kwargs)
  File "/usr/lib/python3.6/site-packages/requests/adapters.py", line 498, in send
    raise ConnectionError(err, request=request)
requests.exceptions.ConnectionError: ('Connection aborted.', ConnectionResetError(104, 'Connection reset by peer'))
2022-08-04 15:53:24,096 (__init__.py:688 MainThread) ERROR - TeleBot: "A request to the Telegram API was unsuccessful. Error code: 409. Description: Conflict: terminated by other getUpdates request; make sure that only one bot instance is running"
<Response [200]>
<Response [200]>
<Response [200]>
<Response [200]>
2022-08-04 15:53:58,980 (__init__.py:688 MainThread) ERROR - TeleBot: "A request to the Telegram API was unsuccessful. Error code: 409. Description: Conflict: terminated by other getUpdates request; make sure that only one bot instance is running"
2022-08-04 16:04:53,468 (__init__.py:688 MainThread) ERROR - TeleBot: "A request to the Telegram API was unsuccessful. Error code: 409. Description: Conflict: terminated by other getUpdates request; make sure that only one bot instance is running"
<Response [200]>
<Response [200]>
<Response [200]>
2022-08-04 16:04:58,390 (__init__.py:688 MainThread) ERROR - TeleBot: "A request to the Telegram API was unsuccessful. Error code: 409. Description: Conflict: terminated by other getUpdates request; make sure that only one bot instance is running"
<Response [200]>
Traceback (most recent call last):
  File "/usr/lib/python3.6/site-packages/urllib3/connectionpool.py", line 384, in _make_request
    six.raise_from(e, None)
  File "<string>", line 3, in raise_from
  File "/usr/lib/python3.6/site-packages/urllib3/connectionpool.py", line 380, in _make_request
    httplib_response = conn.getresponse()
  File "/usr/lib64/python3.6/http/client.py", line 1361, in getresponse
    response.begin()
  File "/usr/lib64/python3.6/http/client.py", line 311, in begin
    version, status, reason = self._read_status()
  File "/usr/lib64/python3.6/http/client.py", line 272, in _read_status
    line = str(self.fp.readline(_MAXLINE + 1), "iso-8859-1")
  File "/usr/lib64/python3.6/socket.py", line 586, in readinto
    return self._sock.recv_into(b)
  File "/usr/lib64/python3.6/ssl.py", line 971, in recv_into
    return self.read(nbytes, buffer)
  File "/usr/lib64/python3.6/ssl.py", line 833, in read
    return self._sslobj.read(len, buffer)
  File "/usr/lib64/python3.6/ssl.py", line 590, in read
    v = self._sslobj.read(len, buffer)
socket.timeout: The read operation timed out

During handling of the above exception, another exception occurred:

Traceback (most recent call last):
  File "/usr/lib/python3.6/site-packages/requests/adapters.py", line 449, in send
    timeout=timeout
  File "/usr/lib/python3.6/site-packages/urllib3/connectionpool.py", line 638, in urlopen
    _stacktrace=sys.exc_info()[2])
  File "/usr/lib/python3.6/site-packages/urllib3/util/retry.py", line 368, in increment
    raise six.reraise(type(error), error, _stacktrace)
  File "/usr/lib/python3.6/site-packages/urllib3/packages/six.py", line 693, in reraise
    raise value
  File "/usr/lib/python3.6/site-packages/urllib3/connectionpool.py", line 600, in urlopen
    chunked=chunked)
  File "/usr/lib/python3.6/site-packages/urllib3/connectionpool.py", line 386, in _make_request
    self._raise_timeout(err=e, url=url, timeout_value=read_timeout)
  File "/usr/lib/python3.6/site-packages/urllib3/connectionpool.py", line 306, in _raise_timeout
    raise ReadTimeoutError(self, url, "Read timed out. (read timeout=%s)" % timeout_value)
urllib3.exceptions.ReadTimeoutError: HTTPSConnectionPool(host='api.telegram.org', port=443): Read timed out. (read timeout=25)

During handling of the above exception, another exception occurred:

Traceback (most recent call last):
  File "main.py", line 57, in <module>
    bot.polling()
  File "/usr/local/lib/python3.6/site-packages/telebot/__init__.py", line 658, in polling
    self.__threaded_polling(non_stop, interval, timeout, long_polling_timeout, allowed_updates)
  File "/usr/local/lib/python3.6/site-packages/telebot/__init__.py", line 720, in __threaded_polling
    raise e
  File "/usr/local/lib/python3.6/site-packages/telebot/__init__.py", line 679, in __threaded_polling
    polling_thread.raise_exceptions()
  File "/usr/local/lib/python3.6/site-packages/telebot/util.py", line 105, in raise_exceptions
    raise self.exception_info
  File "/usr/local/lib/python3.6/site-packages/telebot/util.py", line 87, in run
    task(*args, **kwargs)
  File "/usr/local/lib/python3.6/site-packages/telebot/__init__.py", line 409, in __retrieve_updates
    timeout=timeout, long_polling_timeout=long_polling_timeout)
  File "/usr/local/lib/python3.6/site-packages/telebot/__init__.py", line 387, in get_updates
    json_updates = apihelper.get_updates(self.token, offset, limit, timeout, allowed_updates, long_polling_timeout)
  File "/usr/local/lib/python3.6/site-packages/telebot/apihelper.py", line 328, in get_updates
    return _make_request(token, method_url, params=payload)
  File "/usr/local/lib/python3.6/site-packages/telebot/apihelper.py", line 154, in _make_request
    timeout=(connect_timeout, read_timeout), proxies=proxy)
  File "/usr/lib/python3.6/site-packages/requests/sessions.py", line 533, in request
    resp = self.send(prep, **send_kwargs)
  File "/usr/lib/python3.6/site-packages/requests/sessions.py", line 646, in send
    r = adapter.send(request, **kwargs)
  File "/usr/lib/python3.6/site-packages/requests/adapters.py", line 529, in send
    raise ReadTimeout(e, request=request)
requests.exceptions.ReadTimeout: HTTPSConnectionPool(host='api.telegram.org', port=443): Read timed out. (read timeout=25)
<Response [200]>
<Response [200]>
list index out of range
<Response [200]>
<Response [200]>
<Response [200]>
list index out of range
list index out of range
<Response [200]>
Traceback (most recent call last):
  File "/usr/lib/python3.6/site-packages/urllib3/connectionpool.py", line 384, in _make_request
    six.raise_from(e, None)
  File "<string>", line 3, in raise_from
  File "/usr/lib/python3.6/site-packages/urllib3/connectionpool.py", line 380, in _make_request
    httplib_response = conn.getresponse()
  File "/usr/lib64/python3.6/http/client.py", line 1361, in getresponse
    response.begin()
  File "/usr/lib64/python3.6/http/client.py", line 311, in begin
    version, status, reason = self._read_status()
  File "/usr/lib64/python3.6/http/client.py", line 272, in _read_status
    line = str(self.fp.readline(_MAXLINE + 1), "iso-8859-1")
  File "/usr/lib64/python3.6/socket.py", line 586, in readinto
    return self._sock.recv_into(b)
  File "/usr/lib64/python3.6/ssl.py", line 971, in recv_into
    return self.read(nbytes, buffer)
  File "/usr/lib64/python3.6/ssl.py", line 833, in read
    return self._sslobj.read(len, buffer)
  File "/usr/lib64/python3.6/ssl.py", line 590, in read
    v = self._sslobj.read(len, buffer)
socket.timeout: The read operation timed out

During handling of the above exception, another exception occurred:

Traceback (most recent call last):
  File "/usr/lib/python3.6/site-packages/requests/adapters.py", line 449, in send
    timeout=timeout
  File "/usr/lib/python3.6/site-packages/urllib3/connectionpool.py", line 638, in urlopen
    _stacktrace=sys.exc_info()[2])
  File "/usr/lib/python3.6/site-packages/urllib3/util/retry.py", line 368, in increment
    raise six.reraise(type(error), error, _stacktrace)
  File "/usr/lib/python3.6/site-packages/urllib3/packages/six.py", line 693, in reraise
    raise value
  File "/usr/lib/python3.6/site-packages/urllib3/connectionpool.py", line 600, in urlopen
    chunked=chunked)
  File "/usr/lib/python3.6/site-packages/urllib3/connectionpool.py", line 386, in _make_request
    self._raise_timeout(err=e, url=url, timeout_value=read_timeout)
  File "/usr/lib/python3.6/site-packages/urllib3/connectionpool.py", line 306, in _raise_timeout
    raise ReadTimeoutError(self, url, "Read timed out. (read timeout=%s)" % timeout_value)
urllib3.exceptions.ReadTimeoutError: HTTPSConnectionPool(host='api.telegram.org', port=443): Read timed out. (read timeout=25)

During handling of the above exception, another exception occurred:

Traceback (most recent call last):
  File "main.py", line 57, in <module>
    bot.polling()
  File "/usr/local/lib/python3.6/site-packages/telebot/__init__.py", line 658, in polling
    self.__threaded_polling(non_stop, interval, timeout, long_polling_timeout, allowed_updates)
  File "/usr/local/lib/python3.6/site-packages/telebot/__init__.py", line 720, in __threaded_polling
    raise e
  File "/usr/local/lib/python3.6/site-packages/telebot/__init__.py", line 679, in __threaded_polling
    polling_thread.raise_exceptions()
  File "/usr/local/lib/python3.6/site-packages/telebot/util.py", line 105, in raise_exceptions
    raise self.exception_info
  File "/usr/local/lib/python3.6/site-packages/telebot/util.py", line 87, in run
    task(*args, **kwargs)
  File "/usr/local/lib/python3.6/site-packages/telebot/__init__.py", line 409, in __retrieve_updates
    timeout=timeout, long_polling_timeout=long_polling_timeout)
  File "/usr/local/lib/python3.6/site-packages/telebot/__init__.py", line 387, in get_updates
    json_updates = apihelper.get_updates(self.token, offset, limit, timeout, allowed_updates, long_polling_timeout)
  File "/usr/local/lib/python3.6/site-packages/telebot/apihelper.py", line 328, in get_updates
    return _make_request(token, method_url, params=payload)
  File "/usr/local/lib/python3.6/site-packages/telebot/apihelper.py", line 154, in _make_request
    timeout=(connect_timeout, read_timeout), proxies=proxy)
  File "/usr/lib/python3.6/site-packages/requests/sessions.py", line 533, in request
    resp = self.send(prep, **send_kwargs)
  File "/usr/lib/python3.6/site-packages/requests/sessions.py", line 646, in send
    r = adapter.send(request, **kwargs)
  File "/usr/lib/python3.6/site-packages/requests/adapters.py", line 529, in send
    raise ReadTimeout(e, request=request)
requests.exceptions.ReadTimeout: HTTPSConnectionPool(host='api.telegram.org', port=443): Read timed out. (read timeout=25)
